<?xml version="1.0" encoding="utf-8"?>
<!-- This URDF was automatically created by SolidWorks to URDF Exporter! Originally created by Stephen Brawner (brawner@gmail.com) 
     Commit Version: 1.6.0-4-g7f85cfe  Build Version: 1.6.7995.38578
     For more information, please see http://wiki.ros.org/sw_urdf_exporter -->
<robot name="xg1">
  <link name="base">
    <inertial>
      <origin xyz="0.078491 0.00095712 -0.0024899" rpy="0 0 0" />
      <mass value="19.94" />
      <inertia ixx="0.065892" ixy="-0.00079556" ixz="0.0011412" iyy="0.091764" iyz="-0.00013365" izz="0.13084" />
    </inertial>
    <visual>
      <origin xyz="0 0 0" rpy="0 0 0" />
      <geometry>
        <mesh filename="package://xg_description/meshes/base.STL" />
      </geometry>
      <material name="">
        <color rgba="0.75294 0.75294 0.75294 1" />
      </material>
    </visual>
    <!-- <collision>
      <origin xyz="0 0 0" rpy="0 0 0" />
      <geometry>
        <mesh filename="package://xg_description/meshes/base.STL" />
      </geometry>
    </collision> -->
    <collision>
      <origin rpy="0 0 0" xyz="0 0 0" />
      <geometry>
        <box size="0.3762 0.1 0.114" />
      </geometry>
    </collision>
  </link>

  <!--!!!!!!!!!!!! Front Left Leg !!!!!!!!!!!!!!!!!!!!!!!!!!!!!!!!!!!!-->

  <link name="FL_hip">
    <inertial>
      <origin xyz="-0.00266654660496801 0.0133519689988496 4.41673194865648E-05" rpy="0 0 0" />
      <mass value="0.991880093895278" />
      <inertia ixx="0.000735474713644285" ixy="-1.66493793275035E-06" ixz="-6.26863179032235E-07" iyy="0.00125473279179379" iyz="8.02615567106439E-07" izz="0.000688767092339062" />
    </inertial>
    <visual>
      <origin xyz="0 0 0" rpy="0 0 0" />
      <geometry>
        <mesh filename="package://xg_description/meshes/FL_hip.STL" />
      </geometry>
      <material name="">
        <color rgba="0.752941176470588 0.752941176470588 0.752941176470588 1" />
      </material>
    </visual>
    <!-- <collision>
      <origin xyz="0 0 0" rpy="0 0 0" />
      <geometry>
        <mesh filename="package://xg_description/meshes/FL_hip.STL" />
      </geometry>
    </collision> -->
    <collision>
      <origin rpy="1.5707963267948966 0 0" xyz="0 0.12 0" />
      <geometry>
        <cylinder length="0.04" radius="0.046" />
      </geometry>
    </collision>
  </link>
  <joint name="FL_hip_joint" type="revolute">
    <origin xyz="0.1941 0.04 0" rpy="0 0 0" />
    <parent link="base" />
    <child link="FL_hip" />
    <axis xyz="1 0 0" />
    <!-- <limit lower="-0.69813169" upper="0.69813169" effort="23.7" velocity="30.1" /> -->
    <limit lower="-1.0472" upper="1.0472" effort="23.7" velocity="30.1" />
  </joint>
  <link name="FL_thigh">
    <inertial>
      <origin xyz="-0.00125195365313668 0.0194980973093995 -0.0144632914034168" rpy="0 0 0" />
      <mass value="1.2979284128397" />
      <inertia ixx="0.00204180591537494" ixy="-7.59123913111972E-07" ixz="-3.98052964388482E-05" iyy="0.00279939849516335" iyz="-2.9133238939905E-05" izz="0.000922420985624348" />
    </inertial>
    <visual>
      <origin xyz="0 0 0" rpy="0 0 0" />
      <geometry>
        <mesh filename="package://xg_description/meshes/thigh.STL" />
      </geometry>
      <material name="">
        <color rgba="0.752941176470588 0.752941176470588 0.752941176470588 1" />
      </material>
    </visual>
    <!-- <collision>
      <origin xyz="0 0 0" rpy="0 0 0" />
      <geometry>
        <mesh filename="package://xg_description/meshes/thigh.STL" />
      </geometry>
    </collision> -->
    <collision>
      <origin rpy="0 1.5707963267948966 0" xyz="0 0.05 -0.1265" />
      <geometry>
        <box size="0.2 0.0245 0.034" />
      </geometry>
    </collision>
  </link>
  <joint name="FL_thigh_joint" type="revolute">
    <origin xyz="0 0.0666 0" rpy="0 0 0" />
    <parent link="FL_hip" />
    <child link="FL_thigh" />
    <axis xyz="0 1 0" />
    <!-- <limit lower="-1.5708" upper="3.4907" effort="23.7" velocity="30.1" /> -->
    <limit lower="-1.5708" upper="3.4907" effort="23.7" velocity="30.1" />
  </joint>
  <link name="FL_calf">
    <inertial>
      <origin xyz="0.0065868 -1.9919E-07 -0.11305" rpy="0 0 0" />
      <mass value="0.20991" />
      <inertia ixx="0.0011984" ixy="-9.8234E-10" ixz="6.411E-05" iyy="0.0012267" iyz="1.5493E-09" izz="4.9618E-05" />
    </inertial>
    <visual>
      <origin xyz="0 0 0" rpy="0 0 0" />
      <geometry>
        <mesh filename="package://xg_description/meshes/calf.STL" />
      </geometry>
      <material name="">
        <color rgba="0.75294 0.75294 0.75294 1" />
      </material>
    </visual>
    <!-- <collision>
      <origin xyz="0 0 0" rpy="0 0 0" />
      <geometry>
        <mesh filename="package://xg_description/meshes/calf.STL" />
      </geometry>
    </collision> -->
    <collision>
      <origin rpy="0 -0.03 0" xyz="0.0 0 -0.1" />
      <geometry>
        <cylinder length="0.22" radius="0.012" />
      </geometry>
    </collision>
  </link>
  <joint name="FL_calf_joint" type="revolute">
    <origin xyz="0 0.0485 -0.213" rpy="0 0 0" />
    <parent link="FL_thigh" />
    <child link="FL_calf" />
    <axis xyz="0 1 0" />
    <!-- <limit lower="-2.7227" upper="-0.83776" effort="45.43" velocity="15.70" /> -->
    <limit lower="-2.7227" upper="-0.83776" effort="35.55" velocity="20.07" />
  </joint>
  <link name="FL_foot">
    <!-- <contact>
      <friction_anchor/>
      <stiffness value="30000.0"/>
      <damping value="1000.0"/>
      <spinning_friction value="0.3"/>
      <lateral_friction value="1.0"/>
    </contact> -->
    <inertial>
      <origin xyz="-0.00608109957470521 -4.39735801605057E-07 -0.00871302080195785" rpy="0 0 0" />
      <mass value="0.0230877436305375" />
      <inertia ixx="4.56309655971315E-06" ixy="-1.87718789645209E-11" ixz="1.1829507693697E-06" iyy="3.94698437886923E-06" iyz="1.68455504195373E-10" izz="5.42744233742279E-06" />
    </inertial>
    <visual>
      <origin xyz="0 0 0" rpy="0 0 0" />
      <geometry>
        <mesh filename="package://xg_description/meshes/foot.STL" />
      </geometry>
      <material name="">
        <color rgba="0.298039215686275 0.298039215686275 0.298039215686275 1" />
      </material>
    </visual>
    <!-- <collision>
      <origin xyz="0 0 0" rpy="0 0 0" />
      <geometry>
        <mesh filename="package://xg_description/meshes/foot.STL" />
      </geometry>
    </collision> -->
    <collision>
      <origin rpy="0 0 0" xyz="-0.002 0 0" />
      <geometry>
        <sphere radius="0.02" />
      </geometry>
    </collision>
  </link>
  <joint name="FL_foot_joint" type="fixed" dont_collapse="true">
    <origin xyz="0 0 -0.2136" rpy="0 0 0" />
    <parent link="FL_calf" />
    <child link="FL_foot" />
    <axis xyz="0 0 0" />
  </joint>

  <!--!!!!!!!!!!!! Front Right Leg !!!!!!!!!!!!!!!!!!!!!!!!!!!!!!!!!!!!-->
  <link name="FR_hip">
    <inertial>
      <origin xyz="-0.00266650638050733 -0.0133519658969237 4.4157246842964E-05" rpy="0 0 0" />
      <mass value="0.991879380060128" />
      <inertia ixx="0.000735473726450106" ixy="1.66499031420938E-06" ixz="-6.26738158913014E-07" iyy="0.00125473223862785" iyz="-8.0263943045157E-07" izz="0.000688766796338153" />
    </inertial>
    <visual>
      <origin xyz="0 0 0" rpy="0 0 0" />
      <!--modified-->
      <geometry>
        <mesh filename="package://xg_description/meshes/FR_hip.STL" />
      </geometry>
      <material name="">
        <color rgba="0.752941176470588 0.752941176470588 0.752941176470588 1" />
      </material>
    </visual>
    <!-- <collision>
      <origin xyz="0 0 0" rpy="0 0 0" />
      <geometry>
        <mesh filename="package://xg_description/meshes/FR_hip.STL" />
      </geometry>
    </collision> -->
    <collision>
      <origin rpy="1.5707963267948966 0 0" xyz="0 -0.12 0" />
      <geometry>
        <cylinder length="0.04" radius="0.046" />
      </geometry>
    </collision>
  </link>
  <joint name="FR_hip_joint" type="revolute">
    <origin xyz="0.1941 -0.04 0" rpy="0 0 0" />
    <parent link="base" />
    <child link="FR_hip" />
    <axis xyz="1 0 0" />
    <!-- <limit lower="-0.69813169" upper="0.69813169" effort="23.7" velocity="30.1" /> -->
    <limit lower="-1.0472" upper="1.0472" effort="23.7" velocity="30.1" />
  </joint>
  <link name="FR_thigh">
    <inertial>
      <origin xyz="-0.0012536 -0.019494 -0.014461" rpy="0 0 0" />
      <mass value="1.2981" />
      <inertia ixx="0.0020419" ixy="7.5034E-07" ixz="-3.9811E-05" iyy="0.0027996" iyz="2.9156E-05" izz="0.00092257" />
    </inertial>
    <visual>
      <origin xyz="0 0 0" rpy="0 0 0" />
      <geometry>
        <mesh filename="package://xg_description/meshes/thigh_mirror.STL" />
      </geometry>
      <material name="">
        <color rgba="0.75294 0.75294 0.75294 1" />
      </material>
    </visual>
    <!-- <collision>
      <origin xyz="0 0 0" rpy="0 0 0" />
      <geometry>
        <mesh filename="package://xg_description/meshes/thigh_mirror.STL" />
      </geometry>
    </collision> -->
    <collision>
      <origin rpy="0 1.5707963267948966 0" xyz="0 -0.05 -0.1265" />
      <geometry>
        <box size="0.2 0.0245 0.034" />
      </geometry>
    </collision>
  </link>
  <joint name="FR_thigh_joint" type="revolute">
    <origin xyz="0 -0.0666 0" rpy="0 0 0" />
    <parent link="FR_hip" />
    <child link="FR_thigh" />
    <axis xyz="0 1 0" />
    <!-- <limit lower="-1.5708" upper="3.4907" effort="23.7" velocity="30.1" /> -->
    <limit lower="-1.5708" upper="3.4907" effort="23.7" velocity="30.1" />
  </joint>
  <link name="FR_calf">
    <inertial>
      <origin xyz="0.0065873 -4.5378E-08 -0.11305" rpy="0 0 0" />
      <mass value="0.2099" />
      <inertia ixx="0.0011984" ixy="5.2149E-11" ixz="6.4103E-05" iyy="0.0012267" iyz="-2.536E-10" izz="4.9615E-05" />
    </inertial>
    <visual>
      <origin xyz="0 0 0" rpy="0 0 0" />
      <geometry>
        <mesh filename="package://xg_description/meshes/calf_mirror.STL" />
      </geometry>
      <material name="">
        <color rgba="0.75294 0.75294 0.75294 1" />
      </material>
    </visual>
    <!-- <collision>
      <origin xyz="0 0 0" rpy="0 0 0" />
      <geometry>
        <mesh filename="package://xg_description/meshes/calf_mirror.STL" />
      </geometry>
    </collision> -->
    <collision>
      <origin rpy="0 -0.03 0" xyz="0.0 0 -0.1" />
      <geometry>
        <cylinder length="0.22" radius="0.012" />
      </geometry>
    </collision>
  </link>
  <joint name="FR_calf_joint" type="revolute">
    <origin xyz="0 -0.0485 -0.213" rpy="0 0 0" />
    <parent link="FR_thigh" />
    <child link="FR_calf" />
    <axis xyz="0 1 0" />
    <!-- <limit lower="-2.7227" upper="-0.83776" effort="45.43" velocity="15.70" /> -->
    <limit lower="-2.7227" upper="-0.83776" effort="35.55" velocity="20.07" />
  </joint>
  <link name="FR_foot">
    <!-- <contact>
      <friction_anchor/>
      <stiffness value="30000.0"/>
      <damping value="1000.0"/>
      <spinning_friction value="0.3"/>
      <lateral_friction value="1.0"/>
    </contact> -->
    <inertial>
      <origin xyz="-0.00608086435994926 -2.15326076213884E-06 -0.00871259010801895" rpy="0 0 0" />
      <mass value="0.0230886127456535" />
      <inertia ixx="4.56314370344166E-06" ixy="5.62929448550105E-11" ixz="1.18306119156897E-06" iyy="3.94744349560794E-06" iyz="-7.77603640594363E-11" izz="5.42757695538125E-06" />
    </inertial>
    <visual>
      <origin xyz="0 0 0" rpy="0 0 0" />
      <geometry>
        <mesh filename="package://xg_description/meshes/foot.STL" />
      </geometry>
      <material name="">
        <color rgba="0.647058823529412 0.619607843137255 0.588235294117647 1" />
      </material>
    </visual>
    <!-- <collision>
      <origin xyz="0 0 0" rpy="0 0 0" />
      <geometry>
        <mesh filename="package://xg_description/meshes/foot.STL" />
      </geometry>
    </collision> -->
    <collision>
      <origin rpy="0 0 0" xyz="-0.002 0 0" />
      <geometry>
        <sphere radius="0.02" />
      </geometry>
    </collision>
  </link>
  <joint name="FR_foot_joint" type="fixed" dont_collapse="true">
    <origin xyz="0 0 -0.2136" rpy="0 0 0" />
    <parent link="FR_calf" />
    <child link="FR_foot" />
    <axis xyz="0 0 0" />
  </joint>

  <!--!!!!!!!!!!!! Back Left Leg !!!!!!!!!!!!!!!!!!!!!!!!!!!!!!!!!!!!-->
  <link name="RL_hip">
    <inertial>
      <origin xyz="0.0026665 0.013352 4.4157E-05" rpy="0 0 0" />
      <mass value="0.99188" />
      <inertia ixx="0.00073547" ixy="1.665E-06" ixz="6.2674E-07" iyy="0.0012547" iyz="8.0264E-07" izz="0.00068877" />
    </inertial>
    <visual>
      <origin xyz="0 0 0" rpy="0 0 0" />
      <!-- modified -->
      <geometry>
        <mesh filename="package://xg_description/meshes/RL_hip.STL" />
      </geometry>
      <material name="">
        <color rgba="0.75294 0.75294 0.75294 1" />
      </material>
    </visual>
    <!-- <collision>
      <origin xyz="0 0 0" rpy="0 0 0" />
      <geometry>
        <mesh filename="package://xg_description/meshes/RL_hip.STL" />
      </geometry>
    </collision> -->
    <collision>
      <origin rpy="1.5707963267948966 0 0" xyz="0 0.12 0" />
      <geometry>
        <cylinder length="0.04" radius="0.046" />
      </geometry>
    </collision>
  </link>
  <joint name="RL_hip_joint" type="revolute">
    <origin xyz="-0.1941 0.04 0" rpy="0 0 0" />
    <parent link="base" />
    <child link="RL_hip" />
    <axis xyz="1 0 0" />
    <!-- <limit lower="-0.69813169" upper="0.69813169" effort="23.7" velocity="30.1" /> -->
    <limit lower="-1.0472" upper="1.0472" effort="23.7" velocity="30.1" />
  </joint>
  <link name="RL_thigh">
    <inertial>
      <origin xyz="-0.001252 0.019498 -0.014463" rpy="0 0 0" />
      <mass value="1.2979" />
      <inertia ixx="0.0020418" ixy="-7.5912E-07" ixz="-3.9805E-05" iyy="0.0027994" iyz="-2.9133E-05" izz="0.00092242" />
    </inertial>
    <visual>
      <origin xyz="0 0 0" rpy="0 0 0" />
      <geometry>
        <mesh filename="package://xg_description/meshes/thigh.STL" />
      </geometry>
      <material name="">
        <color rgba="0.75294 0.75294 0.75294 1" />
      </material>
    </visual>
    <!-- <collision>
      <origin xyz="0 0 0" rpy="0 0 0" />
      <geometry>
        <mesh filename="package://xg_description/meshes/thigh.STL" />
      </geometry>
    </collision> -->
    <collision>
      <origin rpy="0 1.5707963267948966 0" xyz="0 0.05 -0.1265" />
      <geometry>
        <box size="0.2 0.0245 0.034" />
      </geometry>
    </collision>
  </link>
  <joint name="RL_thigh_joint" type="revolute">
    <origin xyz="0 0.0666 0" rpy="0 0 0" />
    <parent link="RL_hip" />
    <child link="RL_thigh" />
    <axis xyz="0 1 0" />
    <!-- <limit lower="-0.5236" upper="4.5379" effort="23.7" velocity="30.1" /> -->
    <limit lower="-0.5236" upper="4.5379" effort="23.7" velocity="30.1" />
  </joint>
  <link name="RL_calf">
    <inertial>
      <origin xyz="0.0065873 -4.54E-08 -0.11305" rpy="0 0 0" />
      <mass value="0.2099" />
      <inertia ixx="0.0011984" ixy="5.2131E-11" ixz="6.4103E-05" iyy="0.0012267" iyz="-2.5364E-10" izz="4.9615E-05" />
    </inertial>
    <visual>
      <origin xyz="0 0 0" rpy="0 0 0" />
      <geometry>
        <mesh filename="package://xg_description/meshes/calf.STL" />
      </geometry>
      <material name="">
        <color rgba="0.75294 0.75294 0.75294 1" />
      </material>
    </visual>
    <!-- <collision>
      <origin xyz="0 0 0" rpy="0 0 0" />
      <geometry>
        <mesh filename="package://xg_description/meshes/calf.STL" />
      </geometry>
    </collision> -->
    <collision>
      <origin rpy="0 -0.03 0" xyz="0.0 0 -0.1" />
      <geometry>
        <cylinder length="0.22" radius="0.012" />
      </geometry>
    </collision>
  </link>
  <joint name="RL_calf_joint" type="revolute">
    <origin xyz="0 0.0485 -0.213" rpy="0 0 0" />
    <parent link="RL_thigh" />
    <child link="RL_calf" />
    <axis xyz="0 1 0" />
    <!-- <limit lower="-2.7227" upper="-0.83776" effort="45.43" velocity="15.70" /> -->
    <limit lower="-2.7227" upper="-0.83776" effort="35.55" velocity="20.07" />
  </joint>
  <link name="RL_foot">
    <!-- <contact>
      <friction_anchor/>
      <stiffness value="30000.0"/>
      <damping value="1000.0"/>
      <spinning_friction value="0.3"/>
      <lateral_friction value="1.0"/>
    </contact> -->
    <inertial>
      <origin xyz="-0.0060809 -2.1535E-06 -0.0087126" rpy="0 0 0" />
      <mass value="0.023089" />
      <inertia ixx="4.5631E-06" ixy="5.6274E-11" ixz="1.1831E-06" iyy="3.9474E-06" iyz="-7.7803E-11" izz="5.4276E-06" />
    </inertial>
    <visual>
      <origin xyz="0 0 0" rpy="0 0 0" />
      <geometry>
        <mesh filename="package://xg_description/meshes/foot.STL" />
      </geometry>
      <material name="">
        <color rgba="0.64706 0.61961 0.58824 1" />
      </material>
    </visual>
    <!-- <collision>
      <origin xyz="0 0 0" rpy="0 0 0" />
      <geometry>
        <mesh filename="package://xg_description/meshes/foot.STL" />
      </geometry>
    </collision>  -->
    <collision>
      <origin rpy="0 0 0" xyz="-0.002 0 0" />
      <geometry>
        <sphere radius="0.02" />
      </geometry>
    </collision>
  </link>
  <joint name="RL_foot_joint" type="fixed" dont_collapse="true">
    <origin xyz="0 0 -0.2136" rpy="0 0 0" />
    <parent link="RL_calf" />
    <child link="RL_foot" />
    <axis xyz="0 0 0" />
  </joint>

  <!--!!!!!!!!!!!! Back Right Leg !!!!!!!!!!!!!!!!!!!!!!!!!!!!!!!!!!!!-->
  <link name="RR_hip">
    <inertial>
      <origin xyz="0.0026665 -0.013352 4.4167E-05" rpy="0 0 0" />
      <mass value="0.99188" />
      <inertia ixx="0.00073547" ixy="-1.6649E-06" ixz="6.2686E-07" iyy="0.0012547" iyz="-8.0262E-07" izz="0.00068877" />
    </inertial>
    <visual>
      <origin xyz="0 0 0" rpy="0 0 0" />
      <!-- modified -->
      <geometry>
        <mesh filename="package://xg_description/meshes/RR_hip.STL" />
      </geometry>
      <material name="">
        <color rgba="0.75294 0.75294 0.75294 1" />
      </material>
    </visual>
    <!-- <collision>
      <origin xyz="0 0 0" rpy="0 0 0" />
      <geometry>
        <mesh filename="package://xg_description/meshes/RR_hip.STL" />
      </geometry>
    </collision> -->
    <collision>
      <origin rpy="1.5707963267948966 0 0" xyz="0 -0.12 0" />
      <geometry>
        <cylinder length="0.04" radius="0.046" />
      </geometry>
    </collision>
  </link>
  <joint name="RR_hip_joint" type="revolute">
    <origin xyz="-0.1941 -0.04 0" rpy="0 0 0" />
    <parent link="base" />
    <child link="RR_hip" />
    <axis xyz="1 0 0" />
    <!-- <limit lower="-0.69813169" upper="0.69813169" effort="23.7" velocity="30.1" /> -->
    <limit lower="-1.0472" upper="1.0472" effort="23.7" velocity="30.1" />
  </joint>
  <link name="RR_thigh">
    <inertial>
      <origin xyz="-0.0012536 -0.019494 -0.014461" rpy="0 0 0" />
      <mass value="1.2981" />
      <inertia ixx="0.0020419" ixy="7.5034E-07" ixz="-3.9811E-05" iyy="0.0027996" iyz="2.9156E-05" izz="0.00092257" />
    </inertial>
    <visual>
      <origin xyz="0 0 0" rpy="0 0 0" />
      <geometry>
        <mesh filename="package://xg_description/meshes/thigh_mirror.STL" />
      </geometry>
      <material name="">
        <color rgba="0.75294 0.75294 0.75294 1" />
      </material>
    </visual>
    <!-- <collision>
      <origin xyz="0 0 0" rpy="0 0 0" />
      <geometry>
        <mesh filename="package://xg_description/meshes/thigh_mirror.STL" />
      </geometry>
    </collision> -->
    <collision>
      <origin rpy="0 1.5707963267948966 0" xyz="0 -0.05 -0.1265" />
      <geometry>
        <box size="0.2 0.0245 0.034" />
      </geometry>
    </collision>
  </link>
  <joint name="RR_thigh_joint" type="revolute">
    <origin xyz="0 -0.0666 0" rpy="0 0 0" />
    <parent link="RR_hip" />
    <child link="RR_thigh" />
    <axis xyz="0 1 0" />
    <!-- <limit lower="-0.5236" upper="4.5379" effort="23.7" velocity="30.1" /> -->
    <limit lower="-0.5236" upper="4.5379" effort="23.7" velocity="30.1" />
  </joint>
  <link name="RR_calf">
    <inertial>
      <origin xyz="0.00658683096244933 -1.99191476701888E-07 -0.11305122821908" rpy="0 0 0" />
      <mass value="0.20991129013191" />
      <inertia ixx="0.00119843826172127" ixy="-9.82348500012085E-10" ixz="6.41098393119251E-05" iyy="0.00122672455178647" iyz="1.5493094733436E-09" izz="4.96183651310849E-05" />
    </inertial>
    <visual>
      <origin xyz="0 0 0" rpy="0 0 0" />
      <geometry>
        <mesh filename="package://xg_description/meshes/calf_mirror.STL" />
      </geometry>
      <material name="">
        <color rgba="0.752941176470588 0.752941176470588 0.752941176470588 1" />
      </material>
    </visual>
    <!-- <collision>
      <origin xyz="0 0 0" rpy="0 0 0" />
      <geometry>
        <mesh filename="package://xg_description/meshes/calf_mirror.STL" />
      </geometry>
    </collision> -->
    <collision>
      <origin rpy="0 -0.03 0" xyz="0.0 0 -0.1" />
      <geometry>
        <cylinder length="0.22" radius="0.012" />
      </geometry>
    </collision>
  </link>
  <joint name="RR_calf_joint" type="revolute">
    <origin xyz="0 -0.0485 -0.213" rpy="0 0 0" />
    <parent link="RR_thigh" />
    <child link="RR_calf" />
    <axis xyz="0 1 0" />
    <!-- <limit lower="-2.7227" upper="-0.83776" effort="45.43" velocity="15.70" /> -->
    <limit lower="-2.7227" upper="-0.83776" effort="35.55" velocity="20.07" />
  </joint>
  <link name="RR_foot">
    <!-- <contact>
      <friction_anchor/>
      <stiffness value="30000.0"/>
      <damping value="1000.0"/>
      <spinning_friction value="0.3"/>
      <lateral_friction value="1.0"/>
    </contact> -->
    <inertial>
      <origin xyz="-0.00608109931924855 -4.39706707683341E-07 -0.00871302091971343" rpy="0 0 0" />
      <mass value="0.023087743666312" />
      <inertia ixx="4.56309656192704E-06" ixy="-1.87849181390455E-11" ixz="1.18295078586279E-06" iyy="3.94698440708119E-06" iyz="1.68466818285992E-10" izz="5.42744236105685E-06" />
    </inertial>
    <visual>
      <origin xyz="0 0 0" rpy="0 0 0" />
      <geometry>
        <mesh filename="package://xg_description/meshes/foot.STL" />
      </geometry>
      <material name="">
        <color rgba="0.647058823529412 0.619607843137255 0.588235294117647 1" />
      </material>
    </visual>
    <!-- <collision>
      <origin xyz="0 0 0" rpy="0 0 0" />
      <geometry>
        <mesh filename="package://xg_description/meshes/foot.STL" />
      </geometry>
    </collision> -->
    <collision>
      <origin rpy="0 0 0" xyz="-0.002 0 0" />
      <geometry>
        <sphere radius="0.02" />
      </geometry>
    </collision>
  </link>
  <joint name="RR_foot_joint" type="fixed" dont_collapse="true">
    <origin xyz="0 0 -0.2136" rpy="0 0 0" />
    <parent link="RR_calf" />
    <child link="RR_foot" />
    <axis xyz="0 0 0" />
  </joint>

  <!-- <link name="camera_link">
    <inertial>
      <origin xyz="-0.00502 0 6.9389E-18" rpy="0 0 0" />
      <mass value="0.00091384" />
      <inertia ixx="1.1512E-08" ixy="5.806E-26" ixz="-1.7438E-40" iyy="1.3432E-08" iyz="1.7509E-24" izz="1.3432E-08" />
    </inertial>
    <visual>
      <origin xyz="0 0 0" rpy="0 0 0" />
      <geometry>
        <mesh filename="package://xg_description/meshes/camera.STL" />
      </geometry>
      <material name="">
        <color rgba="0.79608 0.82353 0.93725 1" />
      </material>
    </visual>
    <collision>
      <origin xyz="0 0 0" rpy="0 0 0" />
      <geometry>
        <mesh filename="package://xg_description/meshes/camera.STL" />
      </geometry>
    </collision>
  </link>
  <joint name="camera_joint" type="fixed">
    <origin xyz="0.30954 0 0.043752" rpy="-1.57 0 -1.57" />
    <parent link="base" />
    <child link="camera_link" />
    <axis xyz="0 0 0" />
  </joint> -->


  <!-- <link name="radar_link">
    <inertial>
      <origin xyz="-0.0059263 3.3526E-09 0.016282" rpy="0 0 0" />
      <mass value="0.12676" />
      <inertia ixx="5.5595E-05" ixy="6.4958E-11" ixz="7.6324E-06" iyy="5.8372E-05" iyz="-4.3556E-10" izz="3.7402E-05" />
    </inertial>
    <visual>
      <origin xyz="0 0 0" rpy="0 0 0" />
      <geometry>
        <mesh filename="package://xg_description/meshes/radar.stl" />
      </geometry>
      <material name="">
        <color rgba="0.79608 0.82353 0.93725 1" />
      </material>
    </visual>
    <collision>
      <origin xyz="0 0 0" rpy="0 0 0" />
      <geometry>
        <mesh filename="package://xg_description/meshes/radar.stl" />
      </geometry>
    </collision>
  </link>
  <joint name="radar_joint" type="fixed">
    <origin xyz="0.2841 0 -0.097002" rpy="0 2.49 0" />
    <parent link="base" />
    <child link="radar_link" />
    <axis xyz="0 0 0" />
  </joint> -->



  <!-- <link name="imu_link">
    <inertial>
      <origin xyz="0 0 0" rpy="0 0 0" />
      <mass value="0" />
      <inertia ixx="0" ixy="0" ixz="0" iyy="0" iyz="0" izz="0" />
    </inertial>
    <visual>
      <origin xyz="0 0 0" rpy="0 0 0" />
      <geometry>
        <mesh filename="package://xg_description/meshes/imu.STL" />
      </geometry>
      <material name="">
        <color rgba="1 1 1 1" />
      </material>
    </visual>
    <collision>
      <origin xyz="0 0 0" rpy="0 0 0" />
      <geometry>
        <mesh filename="package://xg_description/meshes/imu.STL" />
      </geometry>
    </collision>
  </link>
  <joint name="imu_joint" type="fixed">
    <origin xyz="0 0 -0.075" rpy="0 0 0" />
    <parent link="base" />
    <child link="imu_link" />
    <axis xyz="0 0 0" />
  </joint> -->
</robot>
