<?xml version="1.0" ?>
<!-- =================================================================================== -->
<!-- |    This document was autogenerated by xacro from robot.xacro                    | -->
<!-- |    EDITING THIS FILE BY HAND IS NOT RECOMMENDED                                 | -->
<!-- =================================================================================== -->
<robot name="xg1">
  <material name="black">
    <color rgba="0.0 0.0 0.0 1.0"/>
  </material>
  <material name="blue">
    <color rgba="0.0 0.0 0.8 1.0"/>
  </material>
  <material name="green">
    <color rgba="0.0 0.8 0.0 1.0"/>
  </material>
  <material name="grey">
    <color rgba="0.2 0.2 0.2 0.0"/>
  </material>
  <material name="silver">
    <color rgba="0.9137254901960784 0.9137254901960784 0.8470588235294118 1.0"/>
  </material>
  <material name="orange">
    <color rgba="1.0 0.4235294117647059 0.0392156862745098 1.0"/>
  </material>
  <material name="brown">
    <color rgba="0.8705882352941177 0.8117647058823529 0.7647058823529411 1.0"/>
  </material>
  <material name="red">
    <color rgba="0.8 0.0 0.0 1.0"/>
  </material>
  <material name="white">
    <color rgba="1.0 1.0 1.0 1.0"/>
  </material>
  <!-- <gazebo reference="base">
        <material>Gazebo/Grey</material>
    </gazebo> -->
  <gazebo reference="imu_link">
    <gravity>true</gravity>
    <sensor name="imu_sensor" type="imu">
      <always_on>true</always_on>
      <update_rate>500</update_rate>
      <visualize>true</visualize>
      <topic>__default_topic__</topic>
      <plugin filename="libgazebo_ros_imu_sensor.so" name="imu_plugin">
        <topicName>base_imu</topicName>
        <bodyName>imu_link</bodyName>
        <updateRateHZ>1000.0</updateRateHZ>
        <gaussianNoise>0.0</gaussianNoise>
        <xyzOffset>0 0 0</xyzOffset>
        <rpyOffset>0 0 0</rpyOffset>
        <frameName>imu_link</frameName>
        <!-- <ros>
                    <namespace>imu</namespace>
                    <remapping>~/out:=imu_data</remapping>
                </ros> -->
      </plugin>
      <pose>0 0 0 0 0 0</pose>
    </sensor>
  </gazebo>
  <gazebo>
    <plugin filename="libgazebo_ros_p3d.so" name="p3d_base_controller">
      <ros>
        <argument>odom:=odom/gazebo</argument>
      </ros>
      <body_name>base_link</body_name>
      <frame_name>world</frame_name>
      <update_rate>10.0</update_rate>
      <xyz_offset>0 0 0</xyz_offset>
      <rpy_offset>0 0 0</rpy_offset>
      <gaussian_noise>0.01</gaussian_noise>
    </plugin>
  </gazebo>
  <gazebo reference="base_link">
    <turnGravityOff>false</turnGravityOff>
  </gazebo>
  <gazebo reference="base">
    <mu1>0.2</mu1>
    <mu2>0.2</mu2>
    <kp value="1000000.0"/>
    <kd value="1.0"/>
  </gazebo>
  <!-- FL leg -->
  <gazebo reference="FL_hip">
    <mu1>0.2</mu1>
    <mu2>0.2</mu2>
  </gazebo>
  <gazebo reference="FL_thigh">
    <mu1>0.2</mu1>
    <mu2>0.2</mu2>
    <self_collide>1</self_collide>
    <kp value="1000000.0"/>
    <kd value="1.0"/>
  </gazebo>
  <gazebo reference="FL_calf">
    <mu1>0.2</mu1>
    <mu2>0.2</mu2>
    <self_collide>1</self_collide>
  </gazebo>
  <gazebo reference="FL_foot">
    <mu1>0.6</mu1>
    <mu2>0.6</mu2>
    <self_collide>1</self_collide>
    <kp value="1000000.0"/>
    <kd value="1.0"/>
  </gazebo>
  <!-- FR leg -->
  <gazebo reference="FR_hip">
    <mu1>0.2</mu1>
    <mu2>0.2</mu2>
  </gazebo>
  <gazebo reference="FR_thigh">
    <mu1>0.2</mu1>
    <mu2>0.2</mu2>
    <self_collide>1</self_collide>
    <kp value="1000000.0"/>
    <kd value="1.0"/>
  </gazebo>
  <gazebo reference="FR_calf">
    <mu1>0.2</mu1>
    <mu2>0.2</mu2>
    <self_collide>1</self_collide>
  </gazebo>
  <gazebo reference="FR_foot">
    <mu1>0.6</mu1>
    <mu2>0.6</mu2>
    <self_collide>1</self_collide>
    <kp value="1000000.0"/>
    <kd value="1.0"/>
  </gazebo>
  <!-- RL leg -->
  <gazebo reference="RL_hip">
    <mu1>0.2</mu1>
    <mu2>0.2</mu2>
  </gazebo>
  <gazebo reference="RL_thigh">
    <mu1>0.2</mu1>
    <mu2>0.2</mu2>
    <self_collide>1</self_collide>
    <kp value="1000000.0"/>
    <kd value="1.0"/>
  </gazebo>
  <gazebo reference="RL_calf">
    <mu1>0.2</mu1>
    <mu2>0.2</mu2>
    <self_collide>1</self_collide>
  </gazebo>
  <gazebo reference="RL_foot">
    <mu1>0.6</mu1>
    <mu2>0.6</mu2>
    <self_collide>1</self_collide>
    <kp value="1000000.0"/>
    <kd value="1.0"/>
  </gazebo>
  <!-- RR leg -->
  <gazebo reference="RR_hip">
    <mu1>0.2</mu1>
    <mu2>0.2</mu2>
  </gazebo>
  <gazebo reference="RR_thigh">
    <mu1>0.2</mu1>
    <mu2>0.2</mu2>
    <self_collide>1</self_collide>
    <kp value="1000000.0"/>
    <kd value="1.0"/>
  </gazebo>
  <gazebo reference="RR_calf">
    <mu1>0.2</mu1>
    <mu2>0.2</mu2>
    <self_collide>1</self_collide>
  </gazebo>
  <gazebo reference="RR_foot">
    <mu1>0.6</mu1>
    <mu2>0.6</mu2>
    <self_collide>1</self_collide>
    <kp value="1000000.0"/>
    <kd value="1.0"/>
  </gazebo>
  <!-- Foot contacts. -->
  <gazebo reference="FR_calf">
    <sensor name="FR_foot_contact" type="contact">
      <update_rate>100</update_rate>
      <plugin filename="libunitree_foot_contact_plugin.so" name="FRcontactPlugin"/>
      <contact>
        <collision>FR_calf_fixed_joint_lump__FR_foot_collision_1</collision>
      </contact>
    </sensor>
  </gazebo>
  <gazebo reference="FL_calf">
    <sensor name="FL_foot_contact" type="contact">
      <update_rate>100</update_rate>
      <plugin filename="libunitree_foot_contact_plugin.so" name="FLcontactPlugin"/>
      <contact>
        <collision>FL_calf_fixed_joint_lump__FL_foot_collision_1</collision>
      </contact>
    </sensor>
  </gazebo>
  <gazebo reference="RR_calf">
    <sensor name="RR_foot_contact" type="contact">
      <update_rate>100</update_rate>
      <plugin filename="libunitree_foot_contact_plugin.so" name="RRcontactPlugin"/>
      <contact>
        <collision>RR_calf_fixed_joint_lump__RR_foot_collision_1</collision>
      </contact>
    </sensor>
  </gazebo>
  <gazebo reference="RL_calf">
    <sensor name="RL_foot_contact" type="contact">
      <update_rate>100</update_rate>
      <plugin filename="libunitree_foot_contact_plugin.so" name="RLcontactPlugin"/>
      <contact>
        <collision>RL_calf_fixed_joint_lump__RL_foot_collision_1</collision>
      </contact>
    </sensor>
  </gazebo>
  <!-- Visualization of Foot contacts. -->
  <gazebo reference="FR_foot">
    <visual>
      <plugin filename="libunitree_draw_force_plugin.so" name="FRdrawForcePlugin">
        <topicName>FR_foot_contact</topicName>
      </plugin>
    </visual>
  </gazebo>
  <gazebo reference="FL_foot">
    <visual>
      <plugin filename="libunitree_draw_force_plugin.so" name="FLdrawForcePlugin">
        <topicName>FL_foot_contact</topicName>
      </plugin>
    </visual>
  </gazebo>
  <gazebo reference="RR_foot">
    <visual>
      <plugin filename="libunitree_draw_force_plugin.so" name="RRdrawForcePlugin">
        <topicName>RR_foot_contact</topicName>
      </plugin>
    </visual>
  </gazebo>
  <gazebo reference="RL_foot">
    <visual>
      <plugin filename="libunitree_draw_force_plugin.so" name="RLdrawForcePlugin">
        <topicName>RL_foot_contact</topicName>
      </plugin>
    </visual>
  </gazebo>
  <joint name="camera_joint" type="fixed">
    <origin rpy="0 0 0" xyz="0.30954 0 0.043752"/>
    <parent link="base"/>
    <child link="camera_link"/>
    <axis xyz="0 0 0"/>
  </joint>
  <link name="camera_link">
    <inertial>
      <origin rpy="0 0 0" xyz="-0.00502 0 6.9389E-18"/>
      <mass value="0.00091384"/>
      <inertia ixx="1.1512E-08" ixy="5.806E-26" ixz="-1.7438E-40" iyy="1.3432E-08" iyz="1.7509E-24" izz="1.3432E-08"/>
    </inertial>
    <visual>
      <origin rpy="0 0 0" xyz="0 0 0"/>
      <geometry>
        <box size="0.03 0.03 0.03"/>
      </geometry>
      <material name="">
        <color rgba="0.79608 0.82353 0.93725 1"/>
      </material>
    </visual>
    <collision>
      <origin rpy="0 0 0" xyz="0 0 0"/>
      <geometry>
        <box size="0.03 0.03 0.03"/>
      </geometry>
    </collision>
  </link>
  <joint name="camera_optical_joint" type="fixed">
    <parent link="camera_link"/>
    <child link="camera_link_optical"/>
    <origin rpy="-1.5707963267948966 0 -1.5707963267948966" xyz="0 0 0"/>
  </joint>
  <link name="camera_link_optical"/>
  <gazebo reference="camera_link">
    <material>Gazebo/Red</material>
    <kinematic>0</kinematic>
    <sensor name="camera_node" type="camera">
      <pose>0 0 0 0 0 0</pose>
      <update_rate>20.0</update_rate>
      <camera name="head">
        <horizontal_fov>1.3962634</horizontal_fov>
        <image>
          <width>1280</width>
          <height>720</height>
          <format>R8G8B8</format>
        </image>
        <clip>
          <near>0.02</near>
          <far>300</far>
        </clip>
        <noise>
          <type>gaussian</type>
          <mean>0.0</mean>
          <stddev>0.007</stddev>
        </noise>
      </camera>
      <plugin filename="libgazebo_ros_camera.so" name="gazebo_camera">
        <alwaysOn>true</alwaysOn>
        <updateRate>0.0</updateRate>
        <cameraName>/camera</cameraName>
        <imageTopicName>image_raw</imageTopicName>
        <cameraInfoTopicName>camera_info</cameraInfoTopicName>
        <frameName>camera_link_optical</frameName>
        <hackBaseline>0.07</hackBaseline>
        <distortionK1>0.0</distortionK1>
        <distortionK2>0.0</distortionK2>
        <distortionK3>0.0</distortionK3>
        <distortionT1>0.0</distortionT1>
        <distortionT2>0.0</distortionT2>
      </plugin>
    </sensor>
  </gazebo>
  <link name="livox_base">
    <inertial>
      <mass value="0.1"/>
      <inertia ixx="0.01" ixy="0" ixz="0" iyy="0.01" iyz="0" izz="0.01"/>
    </inertial>
    <visual>
      <origin rpy="0 0 0" xyz="0.00 0 0.0"/>
      <geometry>
        <mesh filename="file:///home/liangzheng/study_ros_ws/install/xg_description/share/xg_description/meshes/radar.stl">
                                        </mesh>
      </geometry>
    </visual>
  </link>
  <link name="livox">
    <inertial>
      <mass value="0.1"/>
      <inertia ixx="0.01" ixy="0" ixz="0" iyy="0.01" iyz="0" izz="0.01"/>
    </inertial>
  </link>
  <joint name="livox_to_livox_base_joint" type="fixed">
    <parent link="livox_base"/>
    <child link="livox"/>
    <origin rpy="0 0 0" xyz="0.0 0 0.0"/>
  </joint>
  <gazebo reference="livox">
    <sensor name="livox_base" type="ray">
      <pose>0 0 0 0 0 0</pose>
      <visualize>True</visualize>
      <update_rate>100</update_rate>
      <!-- This ray plgin is only for visualization. -->
      <plugin filename="liblivox_laser_simulation_plugin.so" name="gazebo_ros_laser_controller">
        <ray>
          <scan>
            <horizontal>
              <samples>100</samples>
              <resolution>1</resolution>
              <min_angle>-2.3561924999999997</min_angle>
              <max_angle>2.3561924999999997</max_angle>
            </horizontal>
            <vertical>
              <samples>360</samples>
              <resolution>1</resolution>
              <min_angle>-0.12601266555555554</min_angle>
              <max_angle>0.9637699988888888</max_angle>
            </vertical>
          </scan>
          <range>
            <min>0.01</min>
            <max>50.0</max>
            <resolution>0.002</resolution>
          </range>
          <noise>
            <type>gaussian</type>
            <mean>0.0</mean>
            <stddev>0.01</stddev>
          </noise>
        </ray>
        <visualize>True</visualize>
        <samples>24000</samples>
        <downsample>5</downsample>
        <csv_file_name>/home/liangzheng/study_ros_ws/install/xg_description/share/xg_description/scan_mode/mid360.csv</csv_file_name>
        <topic>scan</topic>
      </plugin>
    </sensor>
  </gazebo>
  <joint name="radar_joint" type="fixed">
    <origin rpy="0 2.792527 0" xyz="0.2841 0 -0.097002"/>
    <parent link="base"/>
    <child link="radar_link"/>
    <axis xyz="0 0 0"/>
  </joint>
  <link name="radar_link">
    <inertial>
      <origin rpy="0 0 0" xyz="-0.0059263 3.3526E-09 0.016282"/>
      <mass value="0.12676"/>
      <inertia ixx="5.5595E-05" ixy="6.4958E-11" ixz="7.6324E-06" iyy="5.8372E-05" iyz="-4.3556E-10" izz="3.7402E-05"/>
    </inertial>
    <visual>
      <origin rpy="0 0 0" xyz="0 0 0"/>
      <geometry>
        <box size="0 0 0"/>
      </geometry>
      <material name="">
        <color rgba="0.79608 0.82353 0.93725 1"/>
      </material>
    </visual>
  </link>
  <joint name="radar_to_livox_base_joint" type="fixed">
    <origin rpy="0 0 0" xyz="0.0 0 0"/>
    <parent link="radar_link"/>
    <child link="livox_base"/>
  </joint>
  <link name="base_link">
    <visual>
      <origin rpy="0 0 0" xyz="0 0 0"/>
      <geometry>
        <box size="0.001 0.001 0.001"/>
      </geometry>
    </visual>
  </link>
  <joint name="floating_base" type="fixed">
    <origin rpy="0 0 0" xyz="0 0 0"/>
    <parent link="base_link"/>
    <child link="base"/>
  </joint>
  <link name="base">
    <visual>
      <origin rpy="0 0 0" xyz="0 0 0"/>
      <geometry>
        <mesh filename="file:///home/liangzheng/study_ros_ws/install/xg_description/share/xg_description/meshes/base.STL" scale="1 1 1"/>
        <!-- <box size="${base_length} ${base_width} ${base_height}"/> -->
      </geometry>
      <material name="">
        <color rgba="0.75294 0.75294 0.75294 1"/>
      </material>
    </visual>
    <collision>
      <origin rpy="0 0 0" xyz="0 0 0"/>
      <geometry>
        <box size="0.4 0.1 0.14"/>
      </geometry>
    </collision>
    <inertial>
      <origin rpy="0 0 0" xyz="0.034263 0.0010811 0.0067632"/>
      <mass value="11.33"/>
      <inertia ixx="0.078592" ixy="0.00042233" ixz="0.0030473" iyy="0.21401" iyz="1.7e-05" izz="0.23505"/>
    </inertial>
  </link>
  <joint name="imu_joint" type="fixed">
    <parent link="base"/>
    <child link="imu_link"/>
    <origin rpy="0 0 0" xyz="0 0 0"/>
  </joint>
  <link name="imu_link">
    <inertial>
      <mass value="0.001"/>
      <origin rpy="0 0 0" xyz="0 0 0"/>
      <inertia ixx="0.0001" ixy="0" ixz="0" iyy="0.0001" iyz="0" izz="0.0001"/>
    </inertial>
    <visual>
      <origin rpy="0 0 0" xyz="0 0 0"/>
      <geometry>
        <box size="0.001 0.001 0.001"/>
      </geometry>
      <!-- <material name="red"/> -->
    </visual>
    <collision>
      <origin rpy="0 0 0" xyz="0 0 0"/>
      <geometry>
        <box size=".001 .001 .001"/>
      </geometry>
    </collision>
  </link>
  <joint name="FR_hip_joint" type="revolute">
    <origin rpy="0 0 0" xyz="0.1941 -0.05 0"/>
    <parent link="base"/>
    <child link="FR_hip"/>
    <axis xyz="1 0 0"/>
    <dynamics damping="0.0" friction="0.0"/>
    <limit effort="23.7" lower="-1.0472" upper="1.0472" velocity="30.1"/>
  </joint>
  <link name="FR_hip">
    <visual>
      <origin rpy="0 0 0" xyz="0 0 0"/>
      <geometry>
        <mesh filename="file:///home/liangzheng/study_ros_ws/install/xg_description/share/xg_description/meshes/FR_hip.STL" scale="1 1 1"/>
        <!-- <mesh filename="file://$(find xg_description)/meshes/abad.STL" scale="1 1 1"/> -->
      </geometry>
      <material name="">
        <color rgba="0.752941176470588 0.752941176470588 0.752941176470588 1"/>
      </material>
    </visual>
    <collision>
      <origin rpy="1.5707963267948966 0 0" xyz="0 -0.12 0"/>
      <geometry>
        <cylinder length="0.04" radius="0.046"/>
      </geometry>
    </collision>
    <inertial>
      <origin rpy="0 0 0" xyz="-0.0026063 -0.013225 0.00014"/>
      <mass value="1.0168"/>
      <inertia ixx="0.00102478" ixy="4.22e-06" ixz="-6.32e-06" iyy="0.00147398" iyz="9.16e-06" izz="0.00112511"/>
    </inertial>
  </link>
  <joint name="FR_thigh_joint" type="revolute">
    <origin rpy="0 0 0" xyz="0 -0.0666 0"/>
    <parent link="FR_hip"/>
    <child link="FR_thigh"/>
    <axis xyz="0 1 0"/>
    <dynamics damping="0.0" friction="0.0"/>
    <limit effort="23.7" lower="-1.5708" upper="3.4907" velocity="30.1"/>
  </joint>
  <link name="FR_thigh">
    <visual>
      <origin rpy="0 0 0" xyz="0 0 0"/>
      <geometry>
        <mesh filename="file:///home/liangzheng/study_ros_ws/install/xg_description/share/xg_description/meshes/thigh_mirror.STL" scale="1 1 1"/>
      </geometry>
      <material name="">
        <color rgba="0.752941176470588 0.752941176470588 0.752941176470588 1"/>
      </material>
    </visual>
    <collision>
      <origin rpy="0 1.5707963267948966 0" xyz="0 -0.05 -0.105"/>
      <geometry>
        <box size="0.21 0.0245 0.034"/>
      </geometry>
    </collision>
    <inertial>
      <origin rpy="0 0 0" xyz="-0.00160904 -0.021686 -0.02087162"/>
      <mass value="1.4441"/>
      <inertia ixx="0.0063808" ixy="-5.894e-05" ixz="-0.00021424" iyy="0.00642132" iyz="0.0008594" izz="0.00179976"/>
    </inertial>
  </link>
  <joint name="FR_calf_joint" type="revolute">
    <origin rpy="0 0 0" xyz="0 -0.0485 -0.21"/>
    <parent link="FR_thigh"/>
    <child link="FR_calf"/>
    <axis xyz="0 1 0"/>
    <dynamics damping="0.0" friction="0.0"/>
    <limit effort="35.55" lower="-2.7227" upper="-0.83776" velocity="20.07"/>
  </joint>
  <link name="FR_calf">
    <visual>
      <origin rpy="0 0 0" xyz="0 0 0"/>
      <geometry>
        <mesh filename="file:///home/liangzheng/study_ros_ws/install/xg_description/share/xg_description/meshes/calf_mirror.STL" scale="1 1 1"/>
      </geometry>
      <material name="">
        <color rgba="0.752941176470588 0.752941176470588 0.752941176470588 1"/>
      </material>
    </visual>
    <collision>
      <origin rpy="0 1.5707963267948966 0" xyz="0 0 -0.1075"/>
      <geometry>
        <box size="0.215 0.016 0.016"/>
      </geometry>
    </collision>
    <inertial>
      <origin rpy="0 0 0" xyz="0.00626154 0.0004 -0.116"/>
      <mass value="0.21754"/>
      <inertia ixx="0.00159908" ixy="-8e-08" ixz="2.709e-05" iyy="0.00163205" iyz="5.55e-06" izz="5.678e-05"/>
    </inertial>
  </link>
  <joint dont_collapse="true" name="FR_foot_joint" type="fixed">
    <origin rpy="0 0 0" xyz="0 0 -0.215"/>
    <parent link="FR_calf"/>
    <child link="FR_foot"/>
  </joint>
  <link name="FR_foot">
    <visual>
      <origin rpy="0 0 0" xyz="0 0 0"/>
      <geometry>
        <!-- <sphere radius="${foot_radius-0.01}"/> -->
        <mesh filename="file:///home/liangzheng/study_ros_ws/install/xg_description/share/xg_description/meshes/foot.STL"/>
      </geometry>
      <material name="">
        <color rgba="0.298039215686275 0.298039215686275 0.298039215686275 1"/>
      </material>
    </visual>
    <collision>
      <origin rpy="0 0 0" xyz="0 0 0"/>
      <geometry>
        <sphere radius="0.02"/>
      </geometry>
    </collision>
    <inertial>
      <mass value="0.06"/>
      <inertia ixx="9.600000000000001e-06" ixy="0.0" ixz="0.0" iyy="9.600000000000001e-06" iyz="0.0" izz="9.600000000000001e-06"/>
    </inertial>
  </link>
  <transmission name="FR_hip_tran">
    <type>transmission_interface/SimpleTransmission</type>
    <joint name="FR_hip_joint">
      <hardwareInterface>hardware_interface/EffortJointInterface</hardwareInterface>
    </joint>
    <actuator name="FR_hip_motor">
      <hardwareInterface>hardware_interface/EffortJointInterface</hardwareInterface>
      <mechanicalReduction>1</mechanicalReduction>
    </actuator>
  </transmission>
  <transmission name="FR_thigh_tran">
    <type>transmission_interface/SimpleTransmission</type>
    <joint name="FR_thigh_joint">
      <hardwareInterface>hardware_interface/EffortJointInterface</hardwareInterface>
    </joint>
    <actuator name="FR_thigh_motor">
      <hardwareInterface>hardware_interface/EffortJointInterface</hardwareInterface>
      <mechanicalReduction>1</mechanicalReduction>
    </actuator>
  </transmission>
  <transmission name="FR_calf_tran">
    <type>transmission_interface/SimpleTransmission</type>
    <joint name="FR_calf_joint">
      <hardwareInterface>hardware_interface/EffortJointInterface</hardwareInterface>
    </joint>
    <actuator name="FR_calf_motor">
      <hardwareInterface>hardware_interface/EffortJointInterface</hardwareInterface>
      <mechanicalReduction>1</mechanicalReduction>
    </actuator>
  </transmission>
  <!--for gazebo control-->
  <ros2_control name="FR" type="system">
    <!-- declare hardware interface -->
    <hardware>
      <plugin>gazebo_ros2_control/GazeboSystem</plugin>
      <!--can receive data from gazebo: declare hardware interface-->
    </hardware>
    <!-- declare hardware resources -->
    <joint name="FR_hip_joint">
      <!-- <command_interface name="effort"> control joint command -->
      <!--param is input to resource manager and then send it to hardware interface-->
      <!-- <param name="min">-20</param> -->
      <!-- <param name="min">20</param>                        -->
      <!-- </command_interface> -->
      <command_interface name="effort">
        <param name="min">-23.7</param>
        <param name="max">23.7</param>
      </command_interface>
      <state_interface name="position"/>
      <!-- read data from joint -->
      <state_interface name="velocity"/>
      <!-- read data from joint -->
      <state_interface name="effort"/>
    </joint>
    <joint name="FR_thigh_joint">
      <command_interface name="effort">
        <param name="min">-23.7</param>
        <param name="max">23.7</param>
      </command_interface>
      <state_interface name="position"/>
      <state_interface name="velocity"/>
      <state_interface name="effort"/>
    </joint>
    <joint name="FR_calf_joint">
      <command_interface name="effort">
        <param name="min">-23.7</param>
        <param name="max">23.7</param>
      </command_interface>
      <state_interface name="position"/>
      <state_interface name="velocity"/>
      <state_interface name="effort"/>
    </joint>
  </ros2_control>
  <joint name="FL_hip_joint" type="revolute">
    <origin rpy="0 0 0" xyz="0.1941 0.05 0"/>
    <parent link="base"/>
    <child link="FL_hip"/>
    <axis xyz="1 0 0"/>
    <dynamics damping="0.0" friction="0.0"/>
    <limit effort="23.7" lower="-1.0472" upper="1.0472" velocity="30.1"/>
  </joint>
  <link name="FL_hip">
    <visual>
      <origin rpy="0 0 0" xyz="0 0 0"/>
      <geometry>
        <mesh filename="file:///home/liangzheng/study_ros_ws/install/xg_description/share/xg_description/meshes/FL_hip.STL" scale="1 1 1"/>
        <!-- <mesh filename="file://$(find xg_description)/meshes/abad.STL" scale="1 1 1"/> -->
      </geometry>
      <material name="">
        <color rgba="0.752941176470588 0.752941176470588 0.752941176470588 1"/>
      </material>
    </visual>
    <collision>
      <origin rpy="1.5707963267948966 0 0" xyz="0 0.12 0"/>
      <geometry>
        <cylinder length="0.04" radius="0.046"/>
      </geometry>
    </collision>
    <inertial>
      <origin rpy="0 0 0" xyz="-0.0026063 0.013225 0.00014"/>
      <mass value="1.0168"/>
      <inertia ixx="0.00102478" ixy="-4.22e-06" ixz="-6.32e-06" iyy="0.00147398" iyz="-9.16e-06" izz="0.00112511"/>
    </inertial>
  </link>
  <joint name="FL_thigh_joint" type="revolute">
    <origin rpy="0 0 0" xyz="0 0.0666 0"/>
    <parent link="FL_hip"/>
    <child link="FL_thigh"/>
    <axis xyz="0 1 0"/>
    <dynamics damping="0.0" friction="0.0"/>
    <limit effort="23.7" lower="-1.5708" upper="3.4907" velocity="30.1"/>
  </joint>
  <link name="FL_thigh">
    <visual>
      <origin rpy="0 0 0" xyz="0 0 0"/>
      <geometry>
        <mesh filename="file:///home/liangzheng/study_ros_ws/install/xg_description/share/xg_description/meshes/thigh.STL" scale="1 1 1"/>
      </geometry>
      <material name="">
        <color rgba="0.752941176470588 0.752941176470588 0.752941176470588 1"/>
      </material>
    </visual>
    <collision>
      <origin rpy="0 1.5707963267948966 0" xyz="0 0.05 -0.105"/>
      <geometry>
        <box size="0.21 0.0245 0.034"/>
      </geometry>
    </collision>
    <inertial>
      <origin rpy="0 0 0" xyz="-0.00160904 0.021686 -0.02087162"/>
      <mass value="1.4441"/>
      <inertia ixx="0.0063808" ixy="5.894e-05" ixz="-0.00021424" iyy="0.00642132" iyz="-0.0008594" izz="0.00179976"/>
    </inertial>
  </link>
  <joint name="FL_calf_joint" type="revolute">
    <origin rpy="0 0 0" xyz="0 0.0485 -0.21"/>
    <parent link="FL_thigh"/>
    <child link="FL_calf"/>
    <axis xyz="0 1 0"/>
    <dynamics damping="0.0" friction="0.0"/>
    <limit effort="35.55" lower="-2.7227" upper="-0.83776" velocity="20.07"/>
  </joint>
  <link name="FL_calf">
    <visual>
      <origin rpy="0 0 0" xyz="0 0 0"/>
      <geometry>
        <mesh filename="file:///home/liangzheng/study_ros_ws/install/xg_description/share/xg_description/meshes/calf.STL" scale="1 1 1"/>
      </geometry>
      <material name="">
        <color rgba="0.752941176470588 0.752941176470588 0.752941176470588 1"/>
      </material>
    </visual>
    <collision>
      <origin rpy="0 1.5707963267948966 0" xyz="0 0 -0.1075"/>
      <geometry>
        <box size="0.215 0.016 0.016"/>
      </geometry>
    </collision>
    <inertial>
      <origin rpy="0 0 0" xyz="0.00626154 0.0004 -0.116"/>
      <mass value="0.21754"/>
      <inertia ixx="0.00159908" ixy="-8e-08" ixz="2.709e-05" iyy="0.00163205" iyz="5.55e-06" izz="5.678e-05"/>
    </inertial>
  </link>
  <joint dont_collapse="true" name="FL_foot_joint" type="fixed">
    <origin rpy="0 0 0" xyz="0 0 -0.215"/>
    <parent link="FL_calf"/>
    <child link="FL_foot"/>
  </joint>
  <link name="FL_foot">
    <visual>
      <origin rpy="0 0 0" xyz="0 0 0"/>
      <geometry>
        <!-- <sphere radius="${foot_radius-0.01}"/> -->
        <mesh filename="file:///home/liangzheng/study_ros_ws/install/xg_description/share/xg_description/meshes/foot.STL"/>
      </geometry>
      <material name="">
        <color rgba="0.298039215686275 0.298039215686275 0.298039215686275 1"/>
      </material>
    </visual>
    <collision>
      <origin rpy="0 0 0" xyz="0 0 0"/>
      <geometry>
        <sphere radius="0.02"/>
      </geometry>
    </collision>
    <inertial>
      <mass value="0.06"/>
      <inertia ixx="9.600000000000001e-06" ixy="0.0" ixz="0.0" iyy="9.600000000000001e-06" iyz="0.0" izz="9.600000000000001e-06"/>
    </inertial>
  </link>
  <transmission name="FL_hip_tran">
    <type>transmission_interface/SimpleTransmission</type>
    <joint name="FL_hip_joint">
      <hardwareInterface>hardware_interface/EffortJointInterface</hardwareInterface>
    </joint>
    <actuator name="FL_hip_motor">
      <hardwareInterface>hardware_interface/EffortJointInterface</hardwareInterface>
      <mechanicalReduction>1</mechanicalReduction>
    </actuator>
  </transmission>
  <transmission name="FL_thigh_tran">
    <type>transmission_interface/SimpleTransmission</type>
    <joint name="FL_thigh_joint">
      <hardwareInterface>hardware_interface/EffortJointInterface</hardwareInterface>
    </joint>
    <actuator name="FL_thigh_motor">
      <hardwareInterface>hardware_interface/EffortJointInterface</hardwareInterface>
      <mechanicalReduction>1</mechanicalReduction>
    </actuator>
  </transmission>
  <transmission name="FL_calf_tran">
    <type>transmission_interface/SimpleTransmission</type>
    <joint name="FL_calf_joint">
      <hardwareInterface>hardware_interface/EffortJointInterface</hardwareInterface>
    </joint>
    <actuator name="FL_calf_motor">
      <hardwareInterface>hardware_interface/EffortJointInterface</hardwareInterface>
      <mechanicalReduction>1</mechanicalReduction>
    </actuator>
  </transmission>
  <!--for gazebo control-->
  <ros2_control name="FL" type="system">
    <!-- declare hardware interface -->
    <hardware>
      <plugin>gazebo_ros2_control/GazeboSystem</plugin>
      <!--can receive data from gazebo: declare hardware interface-->
    </hardware>
    <!-- declare hardware resources -->
    <joint name="FL_hip_joint">
      <!-- <command_interface name="effort"> control joint command -->
      <!--param is input to resource manager and then send it to hardware interface-->
      <!-- <param name="min">-20</param> -->
      <!-- <param name="min">20</param>                        -->
      <!-- </command_interface> -->
      <command_interface name="effort">
        <param name="min">-23.7</param>
        <param name="max">23.7</param>
      </command_interface>
      <state_interface name="position"/>
      <!-- read data from joint -->
      <state_interface name="velocity"/>
      <!-- read data from joint -->
      <state_interface name="effort"/>
    </joint>
    <joint name="FL_thigh_joint">
      <command_interface name="effort">
        <param name="min">-23.7</param>
        <param name="max">23.7</param>
      </command_interface>
      <state_interface name="position"/>
      <state_interface name="velocity"/>
      <state_interface name="effort"/>
    </joint>
    <joint name="FL_calf_joint">
      <command_interface name="effort">
        <param name="min">-23.7</param>
        <param name="max">23.7</param>
      </command_interface>
      <state_interface name="position"/>
      <state_interface name="velocity"/>
      <state_interface name="effort"/>
    </joint>
  </ros2_control>
  <joint name="RR_hip_joint" type="revolute">
    <origin rpy="0 0 0" xyz="-0.1941 -0.05 0"/>
    <parent link="base"/>
    <child link="RR_hip"/>
    <axis xyz="1 0 0"/>
    <dynamics damping="0.0" friction="0.0"/>
    <limit effort="23.7" lower="-1.0472" upper="1.0472" velocity="30.1"/>
  </joint>
  <link name="RR_hip">
    <visual>
      <origin rpy="0 0 0" xyz="0 0 0"/>
      <geometry>
        <mesh filename="file:///home/liangzheng/study_ros_ws/install/xg_description/share/xg_description/meshes/RR_hip.STL" scale="1 1 1"/>
        <!-- <mesh filename="file://$(find xg_description)/meshes/abad.STL" scale="1 1 1"/> -->
      </geometry>
      <material name="">
        <color rgba="0.752941176470588 0.752941176470588 0.752941176470588 1"/>
      </material>
    </visual>
    <collision>
      <origin rpy="1.5707963267948966 0 0" xyz="0 -0.12 0"/>
      <geometry>
        <cylinder length="0.04" radius="0.046"/>
      </geometry>
    </collision>
    <inertial>
      <origin rpy="0 0 0" xyz="0.0026063 -0.013225 0.00014"/>
      <mass value="1.0168"/>
      <inertia ixx="0.00102478" ixy="-4.22e-06" ixz="6.32e-06" iyy="0.00147398" iyz="9.16e-06" izz="0.00112511"/>
    </inertial>
  </link>
  <joint name="RR_thigh_joint" type="revolute">
    <origin rpy="0 0 0" xyz="0 -0.0666 0"/>
    <parent link="RR_hip"/>
    <child link="RR_thigh"/>
    <axis xyz="0 1 0"/>
    <dynamics damping="0.0" friction="0.0"/>
    <limit effort="23.7" lower="-1.5708" upper="3.4907" velocity="30.1"/>
  </joint>
  <link name="RR_thigh">
    <visual>
      <origin rpy="0 0 0" xyz="0 0 0"/>
      <geometry>
        <mesh filename="file:///home/liangzheng/study_ros_ws/install/xg_description/share/xg_description/meshes/thigh_mirror.STL" scale="1 1 1"/>
      </geometry>
      <material name="">
        <color rgba="0.752941176470588 0.752941176470588 0.752941176470588 1"/>
      </material>
    </visual>
    <collision>
      <origin rpy="0 1.5707963267948966 0" xyz="0 -0.05 -0.105"/>
      <geometry>
        <box size="0.21 0.0245 0.034"/>
      </geometry>
    </collision>
    <inertial>
      <origin rpy="0 0 0" xyz="-0.00160904 -0.021686 -0.02087162"/>
      <mass value="1.4441"/>
      <inertia ixx="0.0063808" ixy="-5.894e-05" ixz="-0.00021424" iyy="0.00642132" iyz="0.0008594" izz="0.00179976"/>
    </inertial>
  </link>
  <joint name="RR_calf_joint" type="revolute">
    <origin rpy="0 0 0" xyz="0 -0.0485 -0.21"/>
    <parent link="RR_thigh"/>
    <child link="RR_calf"/>
    <axis xyz="0 1 0"/>
    <dynamics damping="0.0" friction="0.0"/>
    <limit effort="35.55" lower="-2.7227" upper="-0.83776" velocity="20.07"/>
  </joint>
  <link name="RR_calf">
    <visual>
      <origin rpy="0 0 0" xyz="0 0 0"/>
      <geometry>
        <mesh filename="file:///home/liangzheng/study_ros_ws/install/xg_description/share/xg_description/meshes/calf_mirror.STL" scale="1 1 1"/>
      </geometry>
      <material name="">
        <color rgba="0.752941176470588 0.752941176470588 0.752941176470588 1"/>
      </material>
    </visual>
    <collision>
      <origin rpy="0 1.5707963267948966 0" xyz="0 0 -0.1075"/>
      <geometry>
        <box size="0.215 0.016 0.016"/>
      </geometry>
    </collision>
    <inertial>
      <origin rpy="0 0 0" xyz="0.00626154 0.0004 -0.116"/>
      <mass value="0.21754"/>
      <inertia ixx="0.00159908" ixy="-8e-08" ixz="2.709e-05" iyy="0.00163205" iyz="5.55e-06" izz="5.678e-05"/>
    </inertial>
  </link>
  <joint dont_collapse="true" name="RR_foot_joint" type="fixed">
    <origin rpy="0 0 0" xyz="0 0 -0.215"/>
    <parent link="RR_calf"/>
    <child link="RR_foot"/>
  </joint>
  <link name="RR_foot">
    <visual>
      <origin rpy="0 0 0" xyz="0 0 0"/>
      <geometry>
        <!-- <sphere radius="${foot_radius-0.01}"/> -->
        <mesh filename="file:///home/liangzheng/study_ros_ws/install/xg_description/share/xg_description/meshes/foot.STL"/>
      </geometry>
      <material name="">
        <color rgba="0.298039215686275 0.298039215686275 0.298039215686275 1"/>
      </material>
    </visual>
    <collision>
      <origin rpy="0 0 0" xyz="0 0 0"/>
      <geometry>
        <sphere radius="0.02"/>
      </geometry>
    </collision>
    <inertial>
      <mass value="0.06"/>
      <inertia ixx="9.600000000000001e-06" ixy="0.0" ixz="0.0" iyy="9.600000000000001e-06" iyz="0.0" izz="9.600000000000001e-06"/>
    </inertial>
  </link>
  <transmission name="RR_hip_tran">
    <type>transmission_interface/SimpleTransmission</type>
    <joint name="RR_hip_joint">
      <hardwareInterface>hardware_interface/EffortJointInterface</hardwareInterface>
    </joint>
    <actuator name="RR_hip_motor">
      <hardwareInterface>hardware_interface/EffortJointInterface</hardwareInterface>
      <mechanicalReduction>1</mechanicalReduction>
    </actuator>
  </transmission>
  <transmission name="RR_thigh_tran">
    <type>transmission_interface/SimpleTransmission</type>
    <joint name="RR_thigh_joint">
      <hardwareInterface>hardware_interface/EffortJointInterface</hardwareInterface>
    </joint>
    <actuator name="RR_thigh_motor">
      <hardwareInterface>hardware_interface/EffortJointInterface</hardwareInterface>
      <mechanicalReduction>1</mechanicalReduction>
    </actuator>
  </transmission>
  <transmission name="RR_calf_tran">
    <type>transmission_interface/SimpleTransmission</type>
    <joint name="RR_calf_joint">
      <hardwareInterface>hardware_interface/EffortJointInterface</hardwareInterface>
    </joint>
    <actuator name="RR_calf_motor">
      <hardwareInterface>hardware_interface/EffortJointInterface</hardwareInterface>
      <mechanicalReduction>1</mechanicalReduction>
    </actuator>
  </transmission>
  <!--for gazebo control-->
  <ros2_control name="RR" type="system">
    <!-- declare hardware interface -->
    <hardware>
      <plugin>gazebo_ros2_control/GazeboSystem</plugin>
      <!--can receive data from gazebo: declare hardware interface-->
    </hardware>
    <!-- declare hardware resources -->
    <joint name="RR_hip_joint">
      <!-- <command_interface name="effort"> control joint command -->
      <!--param is input to resource manager and then send it to hardware interface-->
      <!-- <param name="min">-20</param> -->
      <!-- <param name="min">20</param>                        -->
      <!-- </command_interface> -->
      <command_interface name="effort">
        <param name="min">-23.7</param>
        <param name="max">23.7</param>
      </command_interface>
      <state_interface name="position"/>
      <!-- read data from joint -->
      <state_interface name="velocity"/>
      <!-- read data from joint -->
      <state_interface name="effort"/>
    </joint>
    <joint name="RR_thigh_joint">
      <command_interface name="effort">
        <param name="min">-23.7</param>
        <param name="max">23.7</param>
      </command_interface>
      <state_interface name="position"/>
      <state_interface name="velocity"/>
      <state_interface name="effort"/>
    </joint>
    <joint name="RR_calf_joint">
      <command_interface name="effort">
        <param name="min">-23.7</param>
        <param name="max">23.7</param>
      </command_interface>
      <state_interface name="position"/>
      <state_interface name="velocity"/>
      <state_interface name="effort"/>
    </joint>
  </ros2_control>
  <joint name="RL_hip_joint" type="revolute">
    <origin rpy="0 0 0" xyz="-0.1941 0.05 0"/>
    <parent link="base"/>
    <child link="RL_hip"/>
    <axis xyz="1 0 0"/>
    <dynamics damping="0.0" friction="0.0"/>
    <limit effort="23.7" lower="-1.0472" upper="1.0472" velocity="30.1"/>
  </joint>
  <link name="RL_hip">
    <visual>
      <origin rpy="0 0 0" xyz="0 0 0"/>
      <geometry>
        <mesh filename="file:///home/liangzheng/study_ros_ws/install/xg_description/share/xg_description/meshes/RL_hip.STL" scale="1 1 1"/>
        <!-- <mesh filename="file://$(find xg_description)/meshes/abad.STL" scale="1 1 1"/> -->
      </geometry>
      <material name="">
        <color rgba="0.752941176470588 0.752941176470588 0.752941176470588 1"/>
      </material>
    </visual>
    <collision>
      <origin rpy="1.5707963267948966 0 0" xyz="0 0.12 0"/>
      <geometry>
        <cylinder length="0.04" radius="0.046"/>
      </geometry>
    </collision>
    <inertial>
      <origin rpy="0 0 0" xyz="0.0026063 0.013225 0.00014"/>
      <mass value="1.0168"/>
      <inertia ixx="0.00102478" ixy="4.22e-06" ixz="6.32e-06" iyy="0.00147398" iyz="-9.16e-06" izz="0.00112511"/>
    </inertial>
  </link>
  <joint name="RL_thigh_joint" type="revolute">
    <origin rpy="0 0 0" xyz="0 0.0666 0"/>
    <parent link="RL_hip"/>
    <child link="RL_thigh"/>
    <axis xyz="0 1 0"/>
    <dynamics damping="0.0" friction="0.0"/>
    <limit effort="23.7" lower="-1.5708" upper="3.4907" velocity="30.1"/>
  </joint>
  <link name="RL_thigh">
    <visual>
      <origin rpy="0 0 0" xyz="0 0 0"/>
      <geometry>
        <mesh filename="file:///home/liangzheng/study_ros_ws/install/xg_description/share/xg_description/meshes/thigh.STL" scale="1 1 1"/>
      </geometry>
      <material name="">
        <color rgba="0.752941176470588 0.752941176470588 0.752941176470588 1"/>
      </material>
    </visual>
    <collision>
      <origin rpy="0 1.5707963267948966 0" xyz="0 0.05 -0.105"/>
      <geometry>
        <box size="0.21 0.0245 0.034"/>
      </geometry>
    </collision>
    <inertial>
      <origin rpy="0 0 0" xyz="-0.00160904 0.021686 -0.02087162"/>
      <mass value="1.4441"/>
      <inertia ixx="0.0063808" ixy="5.894e-05" ixz="-0.00021424" iyy="0.00642132" iyz="-0.0008594" izz="0.00179976"/>
    </inertial>
  </link>
  <joint name="RL_calf_joint" type="revolute">
    <origin rpy="0 0 0" xyz="0 0.0485 -0.21"/>
    <parent link="RL_thigh"/>
    <child link="RL_calf"/>
    <axis xyz="0 1 0"/>
    <dynamics damping="0.0" friction="0.0"/>
    <limit effort="35.55" lower="-2.7227" upper="-0.83776" velocity="20.07"/>
  </joint>
  <link name="RL_calf">
    <visual>
      <origin rpy="0 0 0" xyz="0 0 0"/>
      <geometry>
        <mesh filename="file:///home/liangzheng/study_ros_ws/install/xg_description/share/xg_description/meshes/calf.STL" scale="1 1 1"/>
      </geometry>
      <material name="">
        <color rgba="0.752941176470588 0.752941176470588 0.752941176470588 1"/>
      </material>
    </visual>
    <collision>
      <origin rpy="0 1.5707963267948966 0" xyz="0 0 -0.1075"/>
      <geometry>
        <box size="0.215 0.016 0.016"/>
      </geometry>
    </collision>
    <inertial>
      <origin rpy="0 0 0" xyz="0.00626154 0.0004 -0.116"/>
      <mass value="0.21754"/>
      <inertia ixx="0.00159908" ixy="-8e-08" ixz="2.709e-05" iyy="0.00163205" iyz="5.55e-06" izz="5.678e-05"/>
    </inertial>
  </link>
  <joint dont_collapse="true" name="RL_foot_joint" type="fixed">
    <origin rpy="0 0 0" xyz="0 0 -0.215"/>
    <parent link="RL_calf"/>
    <child link="RL_foot"/>
  </joint>
  <link name="RL_foot">
    <visual>
      <origin rpy="0 0 0" xyz="0 0 0"/>
      <geometry>
        <!-- <sphere radius="${foot_radius-0.01}"/> -->
        <mesh filename="file:///home/liangzheng/study_ros_ws/install/xg_description/share/xg_description/meshes/foot.STL"/>
      </geometry>
      <material name="">
        <color rgba="0.298039215686275 0.298039215686275 0.298039215686275 1"/>
      </material>
    </visual>
    <collision>
      <origin rpy="0 0 0" xyz="0 0 0"/>
      <geometry>
        <sphere radius="0.02"/>
      </geometry>
    </collision>
    <inertial>
      <mass value="0.06"/>
      <inertia ixx="9.600000000000001e-06" ixy="0.0" ixz="0.0" iyy="9.600000000000001e-06" iyz="0.0" izz="9.600000000000001e-06"/>
    </inertial>
  </link>
  <transmission name="RL_hip_tran">
    <type>transmission_interface/SimpleTransmission</type>
    <joint name="RL_hip_joint">
      <hardwareInterface>hardware_interface/EffortJointInterface</hardwareInterface>
    </joint>
    <actuator name="RL_hip_motor">
      <hardwareInterface>hardware_interface/EffortJointInterface</hardwareInterface>
      <mechanicalReduction>1</mechanicalReduction>
    </actuator>
  </transmission>
  <transmission name="RL_thigh_tran">
    <type>transmission_interface/SimpleTransmission</type>
    <joint name="RL_thigh_joint">
      <hardwareInterface>hardware_interface/EffortJointInterface</hardwareInterface>
    </joint>
    <actuator name="RL_thigh_motor">
      <hardwareInterface>hardware_interface/EffortJointInterface</hardwareInterface>
      <mechanicalReduction>1</mechanicalReduction>
    </actuator>
  </transmission>
  <transmission name="RL_calf_tran">
    <type>transmission_interface/SimpleTransmission</type>
    <joint name="RL_calf_joint">
      <hardwareInterface>hardware_interface/EffortJointInterface</hardwareInterface>
    </joint>
    <actuator name="RL_calf_motor">
      <hardwareInterface>hardware_interface/EffortJointInterface</hardwareInterface>
      <mechanicalReduction>1</mechanicalReduction>
    </actuator>
  </transmission>
  <!--for gazebo control-->
  <ros2_control name="RL" type="system">
    <!-- declare hardware interface -->
    <hardware>
      <plugin>gazebo_ros2_control/GazeboSystem</plugin>
      <!--can receive data from gazebo: declare hardware interface-->
    </hardware>
    <!-- declare hardware resources -->
    <joint name="RL_hip_joint">
      <!-- <command_interface name="effort"> control joint command -->
      <!--param is input to resource manager and then send it to hardware interface-->
      <!-- <param name="min">-20</param> -->
      <!-- <param name="min">20</param>                        -->
      <!-- </command_interface> -->
      <command_interface name="effort">
        <param name="min">-23.7</param>
        <param name="max">23.7</param>
      </command_interface>
      <state_interface name="position"/>
      <!-- read data from joint -->
      <state_interface name="velocity"/>
      <!-- read data from joint -->
      <state_interface name="effort"/>
    </joint>
    <joint name="RL_thigh_joint">
      <command_interface name="effort">
        <param name="min">-23.7</param>
        <param name="max">23.7</param>
      </command_interface>
      <state_interface name="position"/>
      <state_interface name="velocity"/>
      <state_interface name="effort"/>
    </joint>
    <joint name="RL_calf_joint">
      <command_interface name="effort">
        <param name="min">-23.7</param>
        <param name="max">23.7</param>
      </command_interface>
      <state_interface name="position"/>
      <state_interface name="velocity"/>
      <state_interface name="effort"/>
    </joint>
  </ros2_control>
  <!-- if we simulate in gazbeo, we need to add the following command -->
  <!-- the following command will launch a controller-manager -->
  <!-- we need to write a robot_control.yaml file to specify which controllers we will use-->
  <!-- when we add the following command, it will automatically generate a controller manager variable-->
  <!-- so we do not need to create a controller manager variable in launch file by hand-->
  <gazebo>
    <plugin filename="libgazebo_ros2_control.so" name="gazebo_ros2_control">
      <!-- <robot_param>robot_description</robot_param>
            <robot_param_node>robot_state_publisher_node</robot_param_node> -->
      <parameters>/home/liangzheng/study_ros_ws/install/robot_bringup/share/robot_bringup/config/xg/robot_control.yaml</parameters>
    </plugin>
  </gazebo>
</robot>
